Workbook

Sheet support_tickets_data
A1: ticket_id | B1: customer_id | C1: issue_type | D1: issue_description | E1: priority | F1: date_submitted | G1: response_time_minutes | H1: resolution_time_minutes | I1: satisfaction_rating | J1: customer_comments | K1: agent_id | L1: resolved
A2: T0001 | B2: C0511 | C2: API Issue | D2: I'm pleased with how my issue was handled. Thanks! | E2: High | F2: 45010 | G2: 240 | H2: 927 | I2: 4 | J2: I'm pleased with how my issue was handled. Thanks! | K2: A004 | L2: =TRUE() -> TRUE
A3: T0002 | B3: C0729 | C3: Login Issue | D3: Excellent service! The agent went above and beyond. | E3: Low | F3: 45022 | G3: 223 | H3: 534 | I3: 5 | J3: The problem still persists. Not resolved yet. | K3: A004 | L3: =FALSE() -> FALSE
A4: T0003 | B4: C0439 | C4: Report Generation | D4: Resolution was satisfactory but could be improved. | E4: Low | F4: 45041 | G4: 214 | H4: 592 | I4: 1 | J4: The issue was escalated quickly, which was appreciated. | K4: A004 | L4: =FALSE() -> FALSE
A5: T0004 | B5: C0100 | C5: Data Import | D5: Agent was very helpful and polite. Great service! | E5: High | F5: 44977 | G5: 110 | H5: 864 | I5: 2 | J5: The issue was resolved quickly. Very satisfied! | K5: A003 | L5: =TRUE() -> TRUE
A6: T0005 | B6: C0258 | C6: Feature Request | D6: My issue was handled well, but follow-up could be better. | E6: Medium | F6: 44944 | G6: 151 | H6: 193 | I6: 2 | J6: The problem still persists. Not resolved yet. | K6: A004 | L6: =FALSE() -> FALSE
A7: T0006 | B7: C0526 | C7: Data Import | D7: It took too long to resolve the issue. Not happy. | E7: Low | F7: 45087 | G7: 134 | H7: 194 | I7: 2 | J7: This is the second time I'm facing this issue. Frustrating! | K7: A002 | L7: =TRUE() -> TRUE
A8: T0007 | B8: C0415 | C8: Feature Request | D8: It took too long to resolve the issue. Not happy. | E8: High | F8: 44936 | G8: 64 | H8: 232 | I8: 1 | J8: The support team was unresponsive at first. | K8: A001 | L8: =FALSE() -> FALSE
A9: T0008 | B9: C0602 | C9: Login Issue | D9: Resolution was satisfactory but could be improved. | E9: Critical | F9: 44979 | G9: 132 | H9: 578 | I9: 5 | J9: Good support but the resolution could have been faster. | K9: A002 | L9: =TRUE() -> TRUE
A10: T0009 | B10: C0934 | C10: API Issue | D10: It took too long to resolve the issue. Not happy. | E10: High | F10: 45100 | G10: 57 | H10: 46 | I10: 4 | J10: This is the second time I'm facing this issue. Frustrating! | K10: A004 | L10: =FALSE() -> FALSE
A11: T0010 | B11: C0410 | C11: Feature Request | D11: Good support but the resolution could have been faster. | E11: Critical | F11: 45013 | G11: 223 | H11: 1230 | I11: 3 | J11: This was a critical issue that took too long to resolve. | K11: A002 | L11: =TRUE() -> TRUE
A12: T0011 | B12: C0966 | C12: Report Generation | D12: Agent was very helpful and polite. Great service! | E12: High | F12: 44997 | G12: 192 | H12: 1284 | I12: 2 | J12: The issue was ignored for too long. Disappointing. | K12: A001 | L12: =FALSE() -> FALSE
A13: T0012 | B13: C0342 | C13: Billing Issue | D13: Excellent service! The agent went above and beyond. | E13: Low | F13: 45053 | G13: 35 | H13: 757 | I13: 4 | J13: The issue was ignored for too long. Disappointing. | K13: A003 | L13: =TRUE() -> TRUE
A14: T0013 | B14: C0942 | C14: Billing Issue | D14: The issue was ignored for too long. Disappointing. | E14: Critical | F14: 44978 | G14: 121 | H14: 738 | I14: 4 | J14: It took too long to resolve the issue. Not happy. | K14: A003 | L14: =FALSE() -> FALSE
A15: T0014 | B15: C0192 | C15: Login Issue | D15: Thank you for resolving my issue quickly. | E15: Low | F15: 45020 | G15: 129 | H15: 999 | I15: 5 | J15: Still waiting for a resolution. Not happy with the delay. | K15: A003 | L15: =FALSE() -> FALSE
A16: T0015 | B16: C0270 | C16: Data Import | D16: The agent understood my problem and solved it efficiently. | E16: High | F16: 45085 | G16: 33 | H16: 657 | I16: 4 | J16: This is the second time I'm facing this issue. Frustrating! | K16: A003 | L16: =TRUE() -> TRUE
A17: T0016 | B17: C0836 | C17: Billing Issue | D17: Thank you for resolving my issue quickly. | E17: High | F17: 45072 | G17: 213 | H17: 361 | I17: 1 | J17: This is the second time I'm facing this issue. Frustrating! | K17: A001 | L17: =FALSE() -> FALSE
A18: T0017 | B18: C0218 | C18: API Issue | D18: I'm pleased with how my issue was handled. Thanks! | E18: Critical | F18: 44991 | G18: 178 | H18: 652 | I18: 4 | J18: This is the second time I'm facing this issue. Frustrating! | K18: A004 | L18: =TRUE() -> TRUE
A19: T0018 | B19: C0481 | C19: UI Bug | D19: Agent was knowledgeable and solved my issue efficiently. | E19: Medium | F19: 45099 | G19: 109 | H19: 278 | I19: 4 | J19: Excellent service! The agent went above and beyond. | K19: A004 | L19: =TRUE() -> TRUE
A20: T0019 | B20: C0108 | C20: Feature Request | D20: It took too long to resolve the issue. Not happy. | E20: High | F20: 45019 | G20: 51 | H20: 293 | I20: 3 | J20: Thank you for resolving my issue quickly. | K20: A005 | L20: =TRUE() -> TRUE
A21: T0020 | B21: C0202 | C21: Data Import | D21: Agent was very helpful and polite. Great service! | E21: Medium | F21: 44998 | G21: 55 | H21: 685 | I21: 1 | J21: Happy with the response time but the resolution was lacking. | K21: A002 | L21: =TRUE() -> TRUE
A22: T0021 | B22: C0863 | C22: API Issue | D22: It took too long to resolve the issue. Not happy. | E22: Medium | F22: 44994 | G22: 145 | H22: 638 | I22: 5 | J22: The issue was resolved quickly. Very satisfied! | K22: A004 | L22: =FALSE() -> FALSE
A23: T0022 | B23: C0447 | C23: Report Generation | D23: The problem still persists. Not resolved yet. | E23: High | F23: 44957 | G23: 112 | H23: 185 | I23: 2 | J23: Agent was knowledgeable and solved my issue efficiently. | K23: A001 | L23: =TRUE() -> TRUE
A24: T0023 | B24: C0386 | C24: Data Import | D24: The agent understood my problem and solved it efficiently. | E24: Medium | F24: 45061 | G24: 149 | H24: 234 | I24: 2 | J24: Agent was knowledgeable and solved my issue efficiently. | K24: A005 | L24: =FALSE() -> FALSE
A25: T0024 | B25: C0928 | C25: Data Import | D25: Happy with the response time but the resolution was lacking. | E25: High | F25: 45048 | G25: 142 | H25: 932 | I25: 1 | J25: The support team was unresponsive at first. | K25: A003 | L25: =TRUE() -> TRUE
A26: T0025 | B26: C0256 | C26: UI Bug | D26: This was a critical issue that took too long to resolve. | E26: High | F26: 45083 | G26: 69 | H26: 347 | I26: 3 | J26: This is the second time I'm facing this issue. Frustrating! | K26: A001 | L26: =TRUE() -> TRUE
A27: T0026 | B27: C0741 | C27: Login Issue | D27: Agent was very helpful and polite. Great service! | E27: Low | F27: 45079 | G27: 188 | H27: 865 | I27: 3 | J27: My issue was handled well, but follow-up could be better. | K27: A004 | L27: =FALSE() -> FALSE
A28: T0027 | B28: C0658 | C28: UI Bug | D28: Agent was knowledgeable and solved my issue efficiently. | E28: Low | F28: 44993 | G28: 172 | H28: 1179 | I28: 5 | J28: Still waiting for a resolution. Not happy with the delay. | K28: A004 | L28: =FALSE() -> FALSE
A29: T0028 | B29: C0988 | C29: UI Bug | D29: Overall satisfied, but the process could be faster. | E29: Low | F29: 44944 | G29: 142 | H29: 1055 | I29: 4 | J29: Excellent service! The agent went above and beyond. | K29: A002 | L29: =TRUE() -> TRUE
A30: T0029 | B30: C0304 | C30: Login Issue | D30: It took too long to resolve the issue. Not happy. | E30: Critical | F30: 45074 | G30: 208 | H30: 719 | I30: 4 | J30: The problem still persists. Not resolved yet. | K30: A004 | L30: =TRUE() -> TRUE
A31: T0030 | B31: C0648 | C31: Billing Issue | D31: The issue was ignored for too long. Disappointing. | E31: Medium | F31: 45071 | G31: 15 | H31: 556 | I31: 1 | J31: This is the second time I'm facing this issue. Frustrating! | K31: A004 | L31: =FALSE() -> FALSE
A32: T0031 | B32: C0195 | C32: Billing Issue | D32: Agent was knowledgeable and solved my issue efficiently. | E32: High | F32: 45090 | G32: 105 | H32: 814 | I32: 1 | J32: Good support but the resolution could have been faster. | K32: A005 | L32: =FALSE() -> FALSE
A33: T0032 | B33: C0412 | C33: Feature Request | D33: Happy with the response time but the resolution was lacking. | E33: High | F33: 44944 | G33: 43 | H33: 105 | I33: 2 | J33: It took too long to resolve the issue. Not happy. | K33: A003 | L33: =FALSE() -> FALSE
A34: T0033 | B34: C0352 | C34: Billing Issue | D34: This is the second time I'm facing this issue. Frustrating! | E34: Low | F34: 45049 | G34: 170 | H34: 1189 | I34: 3 | J34: It took too long to resolve the issue. Not happy. | K34: A003 | L34: =TRUE() -> TRUE
A35: T0034 | B35: C0871 | C35: Data Import | D35: The issue was resolved quickly. Very satisfied! | E35: Low | F35: 45094 | G35: 77 | H35: 650 | I35: 3 | J35: Thank you for resolving my issue quickly. | K35: A003 | L35: =FALSE() -> FALSE
A36: T0035 | B36: C0419 | C36: Billing Issue | D36: The support team was unresponsive at first. | E36: Critical | F36: 45061 | G36: 235 | H36: 717 | I36: 2 | J36: My issue was handled well, but follow-up could be better. | K36: A002 | L36: =TRUE() -> TRUE
A37: T0036 | B37: C0994 | C37: Billing Issue | D37: Resolution was satisfactory but could be improved. | E37: High | F37: 44989 | G37: 36 | H37: 123 | I37: 1 | J37: Agent was very helpful and polite. Great service! | K37: A004 | L37: =FALSE() -> FALSE
A38: T0037 | B38: C0834 | C38: Report Generation | D38: Resolution was satisfactory but could be improved. | E38: Medium | F38: 45001 | G38: 76 | H38: 1363 | I38: 4 | J38: The problem still persists. Not resolved yet. | K38: A002 | L38: =FALSE() -> FALSE
A39: T0038 | B39: C0442 | C39: Login Issue | D39: The issue was escalated quickly, which was appreciated. | E39: High | F39: 45023 | G39: 62 | H39: 948 | I39: 4 | J39: The issue was resolved quickly. Very satisfied! | K39: A005 | L39: =TRUE() -> TRUE
A40: T0039 | B40: C0553 | C40: Data Import | D40: Thank you for resolving my issue quickly. | E40: Low | F40: 45077 | G40: 132 | H40: 1020 | I40: 4 | J40: The issue was ignored for too long. Disappointing. | K40: A005 | L40: =FALSE() -> FALSE
...

Sheet Results
A1: Overall Metrics | B1: Value
A2: Total Tickets | B2: ==COUNTA('support_tickets_data'!A2:A51)
A3: Resolved Tickets | B3: ==COUNTIF('support_tickets_data'!L2:L51, TRUE)
A4: Resolution Rate | B4: ==COUNTIF('support_tickets_data'!L2:L51, TRUE)/COUNTA('support_tickets_data'!A2:A51)
A5: Avg Satisfaction | B5: ==AVERAGE('support_tickets_data'!I2:I51)
A7: Issue Type | B7: Count
A8: API Issue | B8: ==COUNTIF('support_tickets_data'!C2:C51, "API Issue")
A9: Login Issue | B9: ==COUNTIF('support_tickets_data'!C2:C51, "Login Issue")
A10: Report Generation | B10: ==COUNTIF('support_tickets_data'!C2:C51, "Report Generation")
A11: Data Import | B11: ==COUNTIF('support_tickets_data'!C2:C51, "Data Import")
A12: Feature Request | B12: ==COUNTIF('support_tickets_data'!C2:C51, "Feature Request")
A13: Billing Issue | B13: ==COUNTIF('support_tickets_data'!C2:C51, "Billing Issue")
A14: UI Bug | B14: ==COUNTIF('support_tickets_data'!C2:C51, "UI Bug")
A16: Priority | B16: Avg Response Time (m) | C16: Avg Resolution Time (m)
A17: Low | B17: ==AVERAGEIF('support_tickets_data'!E2:E51, "Low", 'support_tickets_data'!G2:G51) | C17: ==AVERAGEIF('support_tickets_data'!E2:E51, "Low", 'support_tickets_data'!H2:H51)
A18: Medium | B18: ==AVERAGEIF('support_tickets_data'!E2:E51, "Medium", 'support_tickets_data'!G2:G51) | C18: ==AVERAGEIF('support_tickets_data'!E2:E51, "Medium", 'support_tickets_data'!H2:H51)
A19: High | B19: ==AVERAGEIF('support_tickets_data'!E2:E51, "High", 'support_tickets_data'!G2:G51) | C19: ==AVERAGEIF('support_tickets_data'!E2:E51, "High", 'support_tickets_data'!H2:H51)
A20: Critical | B20: ==AVERAGEIF('support_tickets_data'!E2:E51, "Critical", 'support_tickets_data'!G2:G51) | C20: ==AVERAGEIF('support_tickets_data'!E2:E51, "Critical", 'support_tickets_data'!H2:H51)
A22: Agent ID | B22: Avg Satisfaction
A23: A001 | B23: ==AVERAGEIF('support_tickets_data'!K2:K51, "A001", 'support_tickets_data'!I2:I51)
A24: A002 | B24: ==AVERAGEIF('support_tickets_data'!K2:K51, "A002", 'support_tickets_data'!I2:I51)
A25: A003 | B25: ==AVERAGEIF('support_tickets_data'!K2:K51, "A003", 'support_tickets_data'!I2:I51)
A26: A004 | B26: ==AVERAGEIF('support_tickets_data'!K2:K51, "A004", 'support_tickets_data'!I2:I51)
A27: A005 | B27: ==AVERAGEIF('support_tickets_data'!K2:K51, "A005", 'support_tickets_data'!I2:I51)
